<?xml version="1.0" encoding="utf-8"?>
<!-- This URDF was automatically created by SolidWorks to URDF Exporter! Originally created by Stephen Brawner (brawner@gmail.com) 
     Commit Version: 1.6.0-1-g15f4949  Build Version: 1.6.7594.29634
     For more information, please see http://wiki.ros.org/sw_urdf_exporter -->
<robot
  name="Manipulator_Vlink">
  <link
    name="base_link">
    <inertial>
      <origin
        xyz="5.81517935860494E-18 3.64890254428675E-18 -2.18069225947685E-18"
        rpy="0 0 0" />
      <mass
        value="4.563502045004" />
      <inertia
        ixx="0.0280984473320404"
        ixy="7.96797717061421E-17"
        ixz="1.04038741340493E-20"
        iyy="0.0169477927066625"
        iyz="1.08880015646914E-18"
        izz="0.0376783082336192" />
    </inertial>
    <visual>
      <origin
        xyz="0 0 0"
        rpy="0 0 0" />
      <geometry>
        <mesh
          filename="package://Manipulator_Vlink/meshes/base_link.STL" />
      </geometry>
      <material
        name="">
        <color
          rgba="0.792156862745098 0.819607843137255 0.933333333333333 1" />
      </material>
    </visual>
    <collision>
      <origin
        xyz="0 0 0"
        rpy="0 0 0" />
      <geometry>
        <mesh
          filename="package://Manipulator_Vlink/meshes/base_link.STL" />
      </geometry>
    </collision>
  </link>
  <link
    name="hip2thigh_lf">
    <inertial>
      <origin
        xyz="6.24976908737392E-18 -0.0614074661588189 -0.00575000000000156"
        rpy="0 0 0" />
      <mass
        value="0.0599999613849593" />
      <inertia
        ixx="0.000155906508351339"
        ixy="2.94476214864048E-21"
        ixz="-9.35046804636312E-21"
        iyy="1.13512134874171E-05"
        iyz="-7.895302478684E-19"
        izz="0.000165935222689896" />
    </inertial>
    <visual>
      <origin
        xyz="0 0 0"
        rpy="0 0 0" />
      <geometry>
        <mesh
          filename="package://Manipulator_Vlink/meshes/hip2thigh_lf.STL" />
      </geometry>
      <material
        name="">
        <color
          rgba="0.792156862745098 0.819607843137255 0.933333333333333 1" />
      </material>
    </visual>
    <collision>
      <origin
        xyz="0 0 0"
        rpy="0 0 0" />
      <geometry>
        <mesh
          filename="package://Manipulator_Vlink/meshes/hip2thigh_lf.STL" />
      </geometry>
    </collision>
  </link>
  <joint
    name="hip_lf"
    type="continuous">
    <origin
      xyz="0.0424247110394242 0.156999999999999 0"
      rpy="1.5707963267949 -1.5707963267949 0" />
    <parent
      link="base_link" />
    <child
      link="hip2thigh_lf" />
    <axis
      xyz="0 0 1" />
  </joint>
  <link
    name="thigh2leg_lf">
    <inertial>
      <origin
        xyz="0 -0.10564758516642 -0.00575000000000064"
        rpy="0 0 0" />
      <mass
        value="0.0763000411167859" />
      <inertia
        ixx="0.000437218386664755"
        ixy="1.6940658945086E-21"
        ixz="1.95072209959967E-20"
        iyy="7.44363321133753E-06"
        iyz="1.46010727006436E-18"
        izz="0.000442980239803143" />
    </inertial>
    <visual>
      <origin
        xyz="0 0 0"
        rpy="0 0 0" />
      <geometry>
        <mesh
          filename="package://Manipulator_Vlink/meshes/thigh2leg_lf.STL" />
      </geometry>
      <material
        name="">
        <color
          rgba="0.792156862745098 0.819607843137255 0.933333333333333 1" />
      </material>
    </visual>
    <collision>
      <origin
        xyz="0 0 0"
        rpy="0 0 0" />
      <geometry>
        <mesh
          filename="package://Manipulator_Vlink/meshes/thigh2leg_lf.STL" />
      </geometry>
    </collision>
  </link>
  <joint
    name="knee_lf"
    type="continuous">
    <origin
      xyz="0 -0.14 -0.011500000000001"
      rpy="0 0 -2.46746214692248" />
    <parent
      link="hip2thigh_lf" />
    <child
      link="thigh2leg_lf" />
    <axis
      xyz="0 0 1" />
  </joint>
  <link
    name="leg2wheel_lf">
    <inertial>
      <origin
        xyz="6.41847686111419E-17 -8.32667268468867E-17 0.0207499999999986"
        rpy="0 0 0" />
      <mass
        value="0.521949966745835" />
      <inertia
        ixx="0.000441450058332931"
        ixy="-1.6940658945086E-21"
        ixz="2.07466425242616E-18"
        iyy="0.000441450058332931"
        iyz="-3.38231691806901E-20"
        izz="0.000733078728294525" />
    </inertial>
    <visual>
      <origin
        xyz="0 0 0"
        rpy="0 0 0" />
      <geometry>
        <mesh
          filename="package://Manipulator_Vlink/meshes/leg2wheel_lf.STL" />
      </geometry>
      <material
        name="">
        <color
          rgba="0.792156862745098 0.819607843137255 0.933333333333333 1" />
      </material>
    </visual>
    <collision>
      <origin
        xyz="0 0 0"
        rpy="0 0 0" />
      <geometry>
        <mesh
          filename="package://Manipulator_Vlink/meshes/leg2wheel_lf.STL" />
      </geometry>
    </collision>
  </link>
  <joint
    name="foot_lf"
    type="continuous">
    <origin
      xyz="0 -0.24 0"
      rpy="0 0 0.827377338905804" />
    <parent
      link="thigh2leg_lf" />
    <child
      link="leg2wheel_lf" />
    <axis
      xyz="0 0 1" />
  </joint>
  <link
    name="hip2thigh_lb">
    <inertial>
      <origin
        xyz="-2.22041654777271E-18 -0.0614074661588189 -0.0057500000000007"
        rpy="0 0 0" />
      <mass
        value="0.0539995474696858" />
      <inertia
        ixx="0.000140314771946862"
        ixy="-7.3868622871195E-21"
        ixz="6.14097015851312E-21"
        iyy="1.02160131007346E-05"
        iyz="6.95482200694126E-19"
        izz="0.000149340545022119" />
    </inertial>
    <visual>
      <origin
        xyz="0 0 0"
        rpy="0 0 0" />
      <geometry>
        <mesh
          filename="package://Manipulator_Vlink/meshes/hip2thigh_lb.STL" />
      </geometry>
      <material
        name="">
        <color
          rgba="0.792156862745098 0.819607843137255 0.933333333333333 1" />
      </material>
    </visual>
    <collision>
      <origin
        xyz="0 0 0"
        rpy="0 0 0" />
      <geometry>
        <mesh
          filename="package://Manipulator_Vlink/meshes/hip2thigh_lb.STL" />
      </geometry>
    </collision>
  </link>
  <joint
    name="hip_lb"
    type="continuous">
    <origin
      xyz="-0.0525752889605756 0.126999999999999 0"
      rpy="1.5707963267949 1.5707963267949 0" />
    <parent
      link="base_link" />
    <child
      link="hip2thigh_lb" />
    <axis
      xyz="0 0 1" />
  </joint>
  <link
    name="thigh2leg_lb">
    <inertial>
      <origin
        xyz="2.77555756156289E-17 -0.126725289376484 0.00574999999999845"
        rpy="0 0 0" />
      <mass
        value="0.0750000161747868" />
      <inertia
        ixx="0.000553987900915235"
        ixy="-1.0249098661777E-19"
        ixz="1.70805329904007E-20"
        iyy="9.43756802822458E-06"
        iyz="-3.3007468040004E-18"
        izz="0.00056177234358694" />
    </inertial>
    <visual>
      <origin
        xyz="0 0 0"
        rpy="0 0 0" />
      <geometry>
        <mesh
          filename="package://Manipulator_Vlink/meshes/thigh2leg_lb.STL" />
      </geometry>
      <material
        name="">
        <color
          rgba="0.792156862745098 0.819607843137255 0.933333333333333 1" />
      </material>
    </visual>
    <collision>
      <origin
        xyz="0 0 0"
        rpy="0 0 0" />
      <geometry>
        <mesh
          filename="package://Manipulator_Vlink/meshes/thigh2leg_lb.STL" />
      </geometry>
    </collision>
  </link>
  <joint
    name="knee_lb"
    type="continuous">
    <origin
      xyz="0 -0.14 0"
      rpy="0 0 2.46746214692248" />
    <parent
      link="hip2thigh_lb" />
    <child
      link="thigh2leg_lb" />
    <axis
      xyz="0 0 1" />
  </joint>
  <link
    name="leg2wheel_lb">
    <inertial>
      <origin
        xyz="-1.15359111152458E-16 -5.55111512312578E-17 -0.0207500000000007"
        rpy="0 0 0" />
      <mass
        value="0.521949966745835" />
      <inertia
        ixx="0.000441450058332931"
        ixy="-1.6940658945086E-21"
        ixz="2.07466425242616E-18"
        iyy="0.000441450058332931"
        iyz="-3.38231691806901E-20"
        izz="0.000733078728294525" />
    </inertial>
    <visual>
      <origin
        xyz="0 0 0"
        rpy="0 0 0" />
      <geometry>
        <mesh
          filename="package://Manipulator_Vlink/meshes/leg2wheel_lb.STL" />
      </geometry>
      <material
        name="">
        <color
          rgba="0.792156862745098 0.819607843137255 0.933333333333333 1" />
      </material>
    </visual>
    <collision>
      <origin
        xyz="0 0 0"
        rpy="0 0 0" />
      <geometry>
        <mesh
          filename="package://Manipulator_Vlink/meshes/leg2wheel_lb.STL" />
      </geometry>
    </collision>
  </link>
  <joint
    name="foot_lb"
    type="continuous">
    <origin
      xyz="0 -0.24 0"
      rpy="0 0 -0.965954301349358" />
    <parent
      link="thigh2leg_lb" />
    <child
      link="leg2wheel_lb" />
    <axis
      xyz="0 0 1" />
  </joint>
  <link
    name="hip2thigh_rf">
    <inertial>
      <origin
        xyz="3.75999866151112E-18 -0.061407466158819 0.00575000000000089"
        rpy="0 0 0" />
      <mass
        value="0.0599999613849593" />
      <inertia
        ixx="0.000155906508351339"
        ixy="9.70283065385988E-21"
        ixz="3.7357474179404E-24"
        iyy="1.13512134874171E-05"
        iyz="-1.08504780314569E-18"
        izz="0.000165935222689896" />
    </inertial>
    <visual>
      <origin
        xyz="0 0 0"
        rpy="0 0 0" />
      <geometry>
        <mesh
          filename="package://Manipulator_Vlink/meshes/hip2thigh_rf.STL" />
      </geometry>
      <material
        name="">
        <color
          rgba="0.792156862745098 0.819607843137255 0.933333333333333 1" />
      </material>
    </visual>
    <collision>
      <origin
        xyz="0 0 0"
        rpy="0 0 0" />
      <geometry>
        <mesh
          filename="package://Manipulator_Vlink/meshes/hip2thigh_rf.STL" />
      </geometry>
    </collision>
  </link>
  <joint
    name="hip_rf"
    type="continuous">
    <origin
      xyz="0.0424247110394264 -0.156999999999998 0"
      rpy="1.5707963267949 -1.5707963267949 0" />
    <parent
      link="base_link" />
    <child
      link="hip2thigh_rf" />
    <axis
      xyz="0 0 1" />
  </joint>
  <link
    name="thigh2leg_rf">
    <inertial>
      <origin
        xyz="2.77555756156289E-17 -0.10564758516642 0.00575000000000223"
        rpy="0 0 0" />
      <mass
        value="0.0763000411167858" />
      <inertia
        ixx="0.000437218386664754"
        ixy="-5.84452733605467E-20"
        ixz="2.47571227334978E-20"
        iyy="7.44363321133752E-06"
        iyz="2.37301864809742E-18"
        izz="0.000442980239803142" />
    </inertial>
    <visual>
      <origin
        xyz="0 0 0"
        rpy="0 0 0" />
      <geometry>
        <mesh
          filename="package://Manipulator_Vlink/meshes/thigh2leg_rf.STL" />
      </geometry>
      <material
        name="">
        <color
          rgba="0.792156862745098 0.819607843137255 0.933333333333333 1" />
      </material>
    </visual>
    <collision>
      <origin
        xyz="0 0 0"
        rpy="0 0 0" />
      <geometry>
        <mesh
          filename="package://Manipulator_Vlink/meshes/thigh2leg_rf.STL" />
      </geometry>
    </collision>
  </link>
  <joint
    name="knee_rf"
    type="continuous">
    <origin
      xyz="0 -0.14 0.0114999999999986"
      rpy="0 0 -2.46746214692248" />
    <parent
      link="hip2thigh_rf" />
    <child
      link="thigh2leg_rf" />
    <axis
      xyz="0 0 1" />
  </joint>
  <link
    name="leg2wheel_rf">
    <inertial>
      <origin
        xyz="5.55111512312578E-17 -1.2490009027033E-16 -0.0207499999999983"
        rpy="0 0 0" />
      <mass
        value="0.521949966745835" />
      <inertia
        ixx="0.00044145005833293"
        ixy="-6.7762635780344E-20"
        ixz="-9.00265480038554E-19"
        iyy="0.00044145005833293"
        iyz="1.86202171434693E-18"
        izz="0.000733078728294525" />
    </inertial>
    <visual>
      <origin
        xyz="0 0 0"
        rpy="0 0 0" />
      <geometry>
        <mesh
          filename="package://Manipulator_Vlink/meshes/leg2wheel_rf.STL" />
      </geometry>
      <material
        name="">
        <color
          rgba="0.792156862745098 0.819607843137255 0.933333333333333 1" />
      </material>
    </visual>
    <collision>
      <origin
        xyz="0 0 0"
        rpy="0 0 0" />
      <geometry>
        <mesh
          filename="package://Manipulator_Vlink/meshes/leg2wheel_rf.STL" />
      </geometry>
    </collision>
  </link>
  <joint
    name="foot_rf"
    type="continuous">
    <origin
      xyz="0 -0.24 0"
      rpy="0 0 -1.15869988791543" />
    <parent
      link="thigh2leg_rf" />
    <child
      link="leg2wheel_rf" />
    <axis
      xyz="0 0 1" />
  </joint>
  <link
    name="hip2thigh_rb">
    <inertial>
      <origin
        xyz="2.52390274270345E-18 -0.0614074661588188 0.0057500000000017"
        rpy="0 0 0" />
      <mass
        value="0.0539995474696858" />
      <inertia
        ixx="0.000140314771946862"
        ixy="8.81418992666397E-21"
        ixz="-8.22543354868639E-23"
        iyy="1.02160131007346E-05"
        iyz="9.66936812718221E-19"
        izz="0.000149340545022119" />
    </inertial>
    <visual>
      <origin
        xyz="0 0 0"
        rpy="0 0 0" />
      <geometry>
        <mesh
          filename="package://Manipulator_Vlink/meshes/hip2thigh_rb.STL" />
      </geometry>
      <material
        name="">
        <color
          rgba="0.792156862745098 0.819607843137255 0.933333333333333 1" />
      </material>
    </visual>
    <collision>
      <origin
        xyz="0 0 0"
        rpy="0 0 0" />
      <geometry>
        <mesh
          filename="package://Manipulator_Vlink/meshes/hip2thigh_rb.STL" />
      </geometry>
    </collision>
  </link>
  <joint
    name="hip_rb"
    type="continuous">
    <origin
      xyz="-0.0525752889605738 -0.126999999999999 0"
      rpy="1.5707963267949 1.5707963267949 0" />
    <parent
      link="base_link" />
    <child
      link="hip2thigh_rb" />
    <axis
      xyz="0 0 1" />
  </joint>
  <link
    name="thigh2leg_rb">
    <inertial>
      <origin
        xyz="1.38777878078145E-17 -0.126725289376484 -0.00574999999999939"
        rpy="0 0 0" />
      <mass
        value="0.0750000161747868" />
      <inertia
        ixx="0.000553987900915235"
        ixy="3.76929661528164E-20"
        ixz="3.51746985882905E-20"
        iyy="9.43756802822457E-06"
        iyz="-3.08428735210413E-18"
        izz="0.00056177234358694" />
    </inertial>
    <visual>
      <origin
        xyz="0 0 0"
        rpy="0 0 0" />
      <geometry>
        <mesh
          filename="package://Manipulator_Vlink/meshes/thigh2leg_rb.STL" />
      </geometry>
      <material
        name="">
        <color
          rgba="0.792156862745098 0.819607843137255 0.933333333333333 1" />
      </material>
    </visual>
    <collision>
      <origin
        xyz="0 0 0"
        rpy="0 0 0" />
      <geometry>
        <mesh
          filename="package://Manipulator_Vlink/meshes/thigh2leg_rb.STL" />
      </geometry>
    </collision>
  </link>
  <joint
    name="knee_rb"
    type="continuous">
    <origin
      xyz="0 -0.14 0"
      rpy="0 0 2.46746214692248" />
    <parent
      link="hip2thigh_rb" />
    <child
      link="thigh2leg_rb" />
    <axis
      xyz="0 0 1" />
  </joint>
  <link
    name="leg2wheel_rb">
    <inertial>
      <origin
        xyz="-8.32667268468867E-17 1.2490009027033E-16 0.020750000000001"
        rpy="0 0 0" />
      <mass
        value="0.521949966745835" />
      <inertia
        ixx="0.00044145005833293"
        ixy="-6.7762635780344E-20"
        ixz="-9.00265480038554E-19"
        iyy="0.00044145005833293"
        iyz="1.86202171434693E-18"
        izz="0.000733078728294525" />
    </inertial>
    <visual>
      <origin
        xyz="0 0 0"
        rpy="0 0 0" />
      <geometry>
        <mesh
          filename="package://Manipulator_Vlink/meshes/leg2wheel_rb.STL" />
      </geometry>
      <material
        name="">
        <color
          rgba="0.792156862745098 0.819607843137255 0.933333333333333 1" />
      </material>
    </visual>
    <collision>
      <origin
        xyz="0 0 0"
        rpy="0 0 0" />
      <geometry>
        <mesh
          filename="package://Manipulator_Vlink/meshes/leg2wheel_rb.STL" />
      </geometry>
    </collision>
  </link>
  <joint
    name="foot_rb"
    type="continuous">
    <origin
      xyz="0 -0.24 0"
      rpy="0 0 -2.95203152817059" />
    <parent
      link="thigh2leg_rb" />
    <child
      link="leg2wheel_rb" />
    <axis
      xyz="0 0 1" />
  </joint>
  <link
    name="r0">
    <inertial>
      <origin
        xyz="0 0 -0.015703"
        rpy="0 0 0" />
      <mass
        value="0.032137" />
      <inertia
        ixx="1.7011E-05"
        ixy="3.5016E-20"
        ixz="-1.9417E-21"
        iyy="2.2374E-05"
        iyz="3.8495E-22"
        izz="1.1799E-05" />
    </inertial>
    <visual>
      <origin
        xyz="0 0 0"
        rpy="0 0 0" />
      <geometry>
        <mesh
          filename="package://Manipulator_Vlink/meshes/r0.STL" />
      </geometry>
      <material
        name="">
        <color
          rgba="1 1 1 1" />
      </material>
    </visual>
    <collision>
      <origin
        xyz="0 0 0"
        rpy="0 0 0" />
      <geometry>
        <mesh
          filename="package://Manipulator_Vlink/meshes/r0.STL" />
      </geometry>
    </collision>
  </link>
  <joint
    name="r0"
    type="continuous">
    <origin
      xyz="0.133224711039426 -0.0679999999999988 -0.0135"
      rpy="3.14159265358979 0 0" />
    <parent
      link="base_link" />
    <child
      link="r0" />
    <axis
      xyz="0 0 -1" />
  </joint>
  <link
    name="r1">
    <inertial>
      <origin
        xyz="0.053294 0.0073283 0"
        rpy="0 0 0" />
      <mass
        value="0.242" />
      <inertia
        ixx="2.796E-05"
        ixy="2.0282E-05"
        ixz="-1.5298E-20"
        iyy="0.00041328"
        iyz="7.5624E-22"
        izz="0.00039365" />
    </inertial>
    <visual>
      <origin
        xyz="0 0 0"
        rpy="0 0 0" />
      <geometry>
        <mesh
          filename="package://Manipulator_Vlink/meshes/r1.STL" />
      </geometry>
      <material
        name="">
        <color
          rgba="1 1 1 1" />
      </material>
    </visual>
    <collision>
      <origin
        xyz="0 0 0"
        rpy="0 0 0" />
      <geometry>
        <mesh
          filename="package://Manipulator_Vlink/meshes/r1.STL" />
      </geometry>
    </collision>
  </link>
  <joint
    name="r1"
    type="continuous">
    <origin
      xyz="0 0.0255 -0.03"
      rpy="3.14159265358979 0 0" />
    <parent
      link="r0" />
    <child
      link="r1" />
    <axis
      xyz="0 1 0" />
  </joint>
  <link
    name="r2">
    <inertial>
      <origin
        xyz="0.037121 0.013604 0"
        rpy="0 0 0" />
      <mass
        value="0.252" />
      <inertia
        ixx="2.669E-05"
        ixy="3.4523E-05"
        ixz="4.1921E-22"
        iyy="0.00024862"
        iyz="-2.6906E-21"
        izz="0.00025306" />
    </inertial>
    <visual>
      <origin
        xyz="0 0 0"
        rpy="0 0 0" />
      <geometry>
        <mesh
          filename="package://Manipulator_Vlink/meshes/r2.STL" />
      </geometry>
      <material
        name="">
        <color
          rgba="1 1 1 1" />
      </material>
    </visual>
    <collision>
      <origin
        xyz="0 0 0"
        rpy="0 0 0" />
      <geometry>
        <mesh
          filename="package://Manipulator_Vlink/meshes/r2.STL" />
      </geometry>
    </collision>
  </link>
  <joint
    name="r2"
    type="continuous">
    <origin
      xyz="0.149999999999999 0.0506800000000011 0"
      rpy="0 0 3.14159265358979" />
    <parent
      link="r1" />
    <child
      link="r2" />
    <axis
      xyz="0 1 0" />
  </joint>
  <link
    name="l0">
    <inertial>
      <origin
        xyz="0 0 -0.0157032224890821"
        rpy="0 0 0" />
      <mass
        value="0.0321371669413124" />
      <inertia
        ixx="1.70114298357478E-05"
        ixy="3.46949388041796E-20"
        ixz="-4.53859709976249E-22"
        iyy="2.237392983736E-05"
        iyz="-2.02793374476733E-22"
        izz="1.17992251230963E-05" />
    </inertial>
    <visual>
      <origin
        xyz="0 0 0"
        rpy="0 0 0" />
      <geometry>
        <mesh
          filename="package://Manipulator_Vlink/meshes/l0.STL" />
      </geometry>
      <material
        name="">
        <color
          rgba="1 1 1 1" />
      </material>
    </visual>
    <collision>
      <origin
        xyz="0 0 0"
        rpy="0 0 0" />
      <geometry>
        <mesh
          filename="package://Manipulator_Vlink/meshes/l0.STL" />
      </geometry>
    </collision>
  </link>
  <joint
    name="l0"
    type="continuous">
    <origin
      xyz="0.133224711039425 0.0680000000000012 -0.0135"
      rpy="-3.14159265358979 0 3.14159265358979" />
    <parent
      link="base_link" />
    <child
      link="l0" />
    <axis
      xyz="0 0 -1" />
  </joint>
  <link
    name="l1">
    <inertial>
      <origin
        xyz="0.053294 0.0073283 6.9389E-18"
        rpy="0 0 0" />
      <mass
        value="0.242" />
      <inertia
        ixx="2.796E-05"
        ixy="2.0282E-05"
        ixz="-5.6835E-20"
        iyy="0.00041328"
        iyz="2.2809E-21"
        izz="0.00039365" />
    </inertial>
    <visual>
      <origin
        xyz="0 0 0"
        rpy="0 0 0" />
      <geometry>
        <mesh
          filename="package://Manipulator_Vlink/meshes/l1.STL" />
      </geometry>
      <material
        name="">
        <color
          rgba="1 1 1 1" />
      </material>
    </visual>
    <collision>
      <origin
        xyz="0 0 0"
        rpy="0 0 0" />
      <geometry>
        <mesh
          filename="package://Manipulator_Vlink/meshes/l1.STL" />
      </geometry>
    </collision>
  </link>
  <joint
    name="l1"
    type="continuous">
    <origin
      xyz="0 0.0255 -0.0300000000000001"
      rpy="0 0 3.14159265358979" />
    <parent
      link="l0" />
    <child
      link="l1" />
    <axis
      xyz="0 1 0" />
  </joint>
  <link
    name="l2">
    <inertial>
      <origin
        xyz="0.037121 0.013604 0"
        rpy="0 0 0" />
      <mass
        value="0.252" />
      <inertia
        ixx="2.669E-05"
        ixy="3.4523E-05"
        ixz="5.4659E-21"
        iyy="0.00024862"
        iyz="-4.2579E-21"
        izz="0.00025306" />
    </inertial>
    <visual>
      <origin
        xyz="0 0 0"
        rpy="0 0 0" />
      <geometry>
        <mesh
          filename="package://Manipulator_Vlink/meshes/l2.STL" />
      </geometry>
      <material
        name="">
        <color
          rgba="1 1 1 1" />
      </material>
    </visual>
    <collision>
      <origin
        xyz="0 0 0"
        rpy="0 0 0" />
      <geometry>
        <mesh
          filename="package://Manipulator_Vlink/meshes/l2.STL" />
      </geometry>
    </collision>
  </link>
  <joint
    name="l2"
    type="continuous">
    <origin
      xyz="0.15 0.0506799999999991 0"
      rpy="0 0 3.14159265358979" />
    <parent
      link="l1" />
    <child
      link="l2" />
    <axis
      xyz="0 1 0" />
  </joint>
  <link
    name="armbase">
    <inertial>
      <origin
        xyz="1.0605E-15 0.010012 0.0027052"
        rpy="0 0 0" />
      <mass
        value="0.384" />
      <inertia
        ixx="7.0477E-05"
        ixy="-3.3653E-20"
        ixz="3.9496E-18"
        iyy="0.00069458"
        iyz="-5.1152E-06"
        izz="0.00065488" />
    </inertial>
    <visual>
      <origin
        xyz="0 0 0"
        rpy="0 0 0" />
      <geometry>
        <mesh
          filename="package://Manipulator_Vlink/meshes/armbase.STL" />
      </geometry>
      <material
        name="">
        <color
          rgba="1 1 1 1" />
      </material>
    </visual>
    <collision>
      <origin
        xyz="0 0 0"
        rpy="0 0 0" />
      <geometry>
        <mesh
          filename="package://Manipulator_Vlink/meshes/armbase.STL" />
      </geometry>
    </collision>
  </link>
  <joint
    name="nonono"
    type="fixed">
    <origin
      xyz="0.125574711039425 0 -0.0525"
      rpy="1.5707963267949 0 1.5707963267949" />
    <parent
      link="base_link" />
    <child
      link="armbase" />
    <axis
      xyz="0 0 0" />
  </joint>
</robot>