<?xml version="1.0" encoding="utf-8"?>
<!-- This URDF was automatically created by SolidWorks to URDF Exporter! Originally created by Stephen Brawner (brawner@gmail.com) 
     Commit Version: 1.6.0-1-g15f4949  Build Version: 1.6.7594.29634
     For more information, please see http://wiki.ros.org/sw_urdf_exporter -->
<robot
  name="robot1">
  <link
    name="body">
    <inertial>
      <origin
        xyz="0 0 0"
        rpy="0 0 0" />
      <mass
        value="4.5635" />
      <inertia
        ixx="0.028108"
        ixy="2.7965E-18"
        ixz="-3.8467E-05"
        iyy="0.016957"
        iyz="0.00023328"
        izz="0.037678" />
    </inertial>
    <visual>
      <origin
        xyz="0 0 0"
        rpy="0 0 0" />
      <geometry>
        <mesh
          filename="package://robot1/meshes/body.STL" />
      </geometry>
      <material
        name="">
        <color
          rgba="0.79216 0.81961 0.93333 1" />
      </material>
    </visual>
    <collision>
      <origin
        xyz="0 0 0"
        rpy="0 0 0" />
      <geometry>
        <mesh
          filename="package://robot1/meshes/body.STL" />
      </geometry>
    </collision>
  </link>
  <link
    name="thigh_lf">
    <inertial>
      <origin
        xyz="-0.00586303520723864 -0.0654186028554409 -0.30825"
        rpy="0 0 0" />
      <mass
        value="0.0599999613849592" />
      <inertia
        ixx="0.000155906508351339"
        ixy="3.87736954528105E-20"
        ixz="-1.90128589635462E-23"
        iyy="1.13512134874171E-05"
        iyz="-9.10641025502815E-22"
        izz="0.000165935222689896" />
    </inertial>
    <visual>
      <origin
        xyz="0 0 0"
        rpy="0 0 0" />
      <geometry>
        <mesh
          filename="package://robot1/meshes/thigh_lf.STL" />
      </geometry>
      <material
        name="">
        <color
          rgba="0.792156862745098 0.819607843137255 0.933333333333333 1" />
      </material>
    </visual>
    <collision>
      <origin
        xyz="0 0 0"
        rpy="0 0 0" />
      <geometry>
        <mesh
          filename="package://robot1/meshes/thigh_lf.STL" />
      </geometry>
    </collision>
  </link>
  <joint
    name="hip_lf"
    type="continuous">
    <origin
      xyz="-0.0384135743428033 -0.471 -0.00659099716673616"
      rpy="1.5707963267949 1.5707963267949 0" />
    <parent
      link="body" />
    <child
      link="thigh_lf" />
    <axis
      xyz="0 0 1" />
  </joint>
  <link
    name="leg_lf">
    <inertial>
      <origin
        xyz="0.00211202615688288 -0.0988649791073192 -0.30825"
        rpy="0 0 0" />
      <mass
        value="0.0763000411167858" />
      <inertia
        ixx="0.000437218386664754"
        ixy="-4.85349878776714E-19"
        ixz="-1.49816179484339E-22"
        iyy="7.44363321133755E-06"
        iyz="1.70699002097028E-21"
        izz="0.000442980239803142" />
    </inertial>
    <visual>
      <origin
        xyz="0 0 0"
        rpy="0 0 0" />
      <geometry>
        <mesh
          filename="package://robot1/meshes/leg_lf.STL" />
      </geometry>
      <material
        name="">
        <color
          rgba="0.792156862745098 0.819607843137255 0.933333333333333 1" />
      </material>
    </visual>
    <collision>
      <origin
        xyz="0 0 0"
        rpy="0 0 0" />
      <geometry>
        <mesh
          filename="package://robot1/meshes/leg_lf.STL" />
      </geometry>
    </collision>
  </link>
  <joint
    name="knee_lf"
    type="continuous">
    <origin
      xyz="0 -0.14 0.0114999999999997"
      rpy="0 0 2.47267049724596" />
    <parent
      link="thigh_lf" />
    <child
      link="leg_lf" />
    <axis
      xyz="0 0 1" />
  </joint>
  <link
    name="wheel_lf">
    <inertial>
      <origin
        xyz="-0.00401113669662187 0.00586303520723827 -0.33475"
        rpy="0 0 0" />
      <mass
        value="0.521949966745835" />
      <inertia
        ixx="0.000441450058332931"
        ixy="8.13744374287306E-52"
        ixz="6.67984372830051E-21"
        iyy="0.000441450058332931"
        iyz="-1.10926466622093E-36"
        izz="0.000733078728294526" />
    </inertial>
    <visual>
      <origin
        xyz="0 0 0"
        rpy="0 0 0" />
      <geometry>
        <mesh
          filename="package://robot1/meshes/wheel_lf.STL" />
      </geometry>
      <material
        name="">
        <color
          rgba="0.792156862745098 0.819607843137255 0.933333333333333 1" />
      </material>
    </visual>
    <collision>
      <origin
        xyz="0 0 0"
        rpy="0 0 0" />
      <geometry>
        <mesh
          filename="package://robot1/meshes/wheel_lf.STL" />
      </geometry>
    </collision>
  </link>
  <joint
    name="wheel_lf"
    type="continuous">
    <origin
      xyz="0 -0.24 0"
      rpy="0 0 -0.901874170451062" />
    <parent
      link="leg_lf" />
    <child
      link="wheel_lf" />
    <axis
      xyz="0 0 1" />
  </joint>
  <link
    name="thigh_lb">
    <inertial>
      <origin
        xyz="0.00586303520723865 -0.057396329462197 -0.30825"
        rpy="0 0 0" />
      <mass
        value="0.0599999613849592" />
      <inertia
        ixx="0.000155906508351339"
        ixy="1.87852681441717E-20"
        ixz="-2.96334987478447E-22"
        iyy="1.13512134874171E-05"
        iyz="-1.06353209176921E-21"
        izz="0.000165935222689896" />
    </inertial>
    <visual>
      <origin
        xyz="0 0 0"
        rpy="0 0 0" />
      <geometry>
        <mesh
          filename="package://robot1/meshes/thigh_lb.STL" />
      </geometry>
      <material
        name="">
        <color
          rgba="0.792156862745098 0.819607843137255 0.933333333333333 1" />
      </material>
    </visual>
    <collision>
      <origin
        xyz="0 0 0"
        rpy="0 0 0" />
      <geometry>
        <mesh
          filename="package://robot1/meshes/thigh_lb.STL" />
      </geometry>
    </collision>
  </link>
  <joint
    name="hip_lb"
    type="continuous">
    <origin
      xyz="0.0565864256571967 -0.441 -0.00464417311367557"
      rpy="1.5707963267949 -1.5707963267949 0" />
    <parent
      link="body" />
    <child
      link="thigh_lb" />
    <axis
      xyz="0 0 1" />
  </joint>
  <link
    name="leg_lb">
    <inertial>
      <origin
        xyz="-0.00708150376026509 -0.126162524831 -0.31975"
        rpy="0 0 0" />
      <mass
        value="0.0750000161747868" />
      <inertia
        ixx="0.000553987900915235"
        ixy="1.52211820621598E-18"
        ixz="-1.21187332340127E-21"
        iyy="9.4375680282246E-06"
        iyz="1.00712625877349E-21"
        izz="0.00056177234358694" />
    </inertial>
    <visual>
      <origin
        xyz="0 0 0"
        rpy="0 0 0" />
      <geometry>
        <mesh
          filename="package://robot1/meshes/leg_lb.STL" />
      </geometry>
      <material
        name="">
        <color
          rgba="0.792156862745098 0.819607843137255 0.933333333333333 1" />
      </material>
    </visual>
    <collision>
      <origin
        xyz="0 0 0"
        rpy="0 0 0" />
      <geometry>
        <mesh
          filename="package://robot1/meshes/leg_lb.STL" />
      </geometry>
    </collision>
  </link>
  <joint
    name="knee_lb"
    type="continuous">
    <origin
      xyz="0 -0.14 0"
      rpy="0 0 -2.46228752890953" />
    <parent
      link="thigh_lb" />
    <child
      link="leg_lb" />
    <axis
      xyz="0 0 1" />
  </joint>
  <link
    name="wheel_lb">
    <inertial>
      <origin
        xyz="-0.00401113669662182 0.00586303520723822 -0.29325"
        rpy="0 0 0" />
      <mass
        value="0.521949966745835" />
      <inertia
        ixx="0.000441450058332931"
        ixy="8.13744374287306E-52"
        ixz="6.67984372830051E-21"
        iyy="0.000441450058332931"
        iyz="-1.10926466622093E-36"
        izz="0.000733078728294526" />
    </inertial>
    <visual>
      <origin
        xyz="0 0 0"
        rpy="0 0 0" />
      <geometry>
        <mesh
          filename="package://robot1/meshes/wheel_lb.STL" />
      </geometry>
      <material
        name="">
        <color
          rgba="0.792156862745098 0.819607843137255 0.933333333333333 1" />
      </material>
    </visual>
    <collision>
      <origin
        xyz="0 0 0"
        rpy="0 0 0" />
      <geometry>
        <mesh
          filename="package://robot1/meshes/wheel_lb.STL" />
      </geometry>
    </collision>
  </link>
  <joint
    name="wheel_lb"
    type="continuous">
    <origin
      xyz="0 -0.24 0"
      rpy="0 0 0.89149120211463" />
    <parent
      link="leg_lb" />
    <child
      link="wheel_lb" />
    <axis
      xyz="0 0 1" />
  </joint>
  <link
    name="thigh_rf">
    <inertial>
      <origin
        xyz="-0.0058630352072386 -0.0654186028554409 -0.30825"
        rpy="0 0 0" />
      <mass
        value="0.0599999613849592" />
      <inertia
        ixx="0.000155906508351339"
        ixy="7.92675361493047E-20"
        ixz="9.30530125579661E-21"
        iyy="1.13512134874171E-05"
        iyz="1.12065382559575E-20"
        izz="0.000165935222689896" />
    </inertial>
    <visual>
      <origin
        xyz="0 0 0"
        rpy="0 0 0" />
      <geometry>
        <mesh
          filename="package://robot1/meshes/thigh_rf.STL" />
      </geometry>
      <material
        name="">
        <color
          rgba="0.792156862745098 0.819607843137255 0.933333333333333 1" />
      </material>
    </visual>
    <collision>
      <origin
        xyz="0 0 0"
        rpy="0 0 0" />
      <geometry>
        <mesh
          filename="package://robot1/meshes/thigh_rf.STL" />
      </geometry>
    </collision>
  </link>
  <joint
    name="hip_rf"
    type="continuous">
    <origin
      xyz="-0.0384135743428034 -0.1455 -0.0104805682225147"
      rpy="1.5707963267949 1.5707963267949 0" />
    <parent
      link="body" />
    <child
      link="thigh_rf" />
    <axis
      xyz="0 0 -1" />
  </joint>
  <link
    name="leg_rf">
    <inertial>
      <origin
        xyz="0.00210380032328554 -0.0988624231462427 -0.31975"
        rpy="0 0 0" />
      <mass
        value="0.0763000411167858" />
      <inertia
        ixx="0.000437218386664754"
        ixy="7.34801081743106E-20"
        ixz="2.62112134099704E-22"
        iyy="7.44363321133753E-06"
        iyz="-4.03252599887136E-19"
        izz="0.000442980239803142" />
    </inertial>
    <visual>
      <origin
        xyz="0 0 0"
        rpy="0 0 0" />
      <geometry>
        <mesh
          filename="package://robot1/meshes/leg_rf.STL" />
      </geometry>
      <material
        name="">
        <color
          rgba="0.792156862745098 0.819607843137255 0.933333333333333 1" />
      </material>
    </visual>
    <collision>
      <origin
        xyz="0 0 0"
        rpy="0 0 0" />
      <geometry>
        <mesh
          filename="package://robot1/meshes/leg_rf.STL" />
      </geometry>
    </collision>
  </link>
  <joint
    name="knee_rf"
    type="continuous">
    <origin
      xyz="0 -0.14 0"
      rpy="0 0 2.47145794223449" />
    <parent
      link="thigh_rf" />
    <child
      link="leg_rf" />
    <axis
      xyz="0 0 1" />
  </joint>
  <link
    name="wheel_rf">
    <inertial>
      <origin
        xyz="-0.00150763839127389 0.00694200445991389 -0.29325"
        rpy="0 0 0" />
      <mass
        value="0.521949966745835" />
      <inertia
        ixx="0.000441450058332931"
        ixy="-1.35525271560688E-20"
        ixz="-2.0780683497093E-20"
        iyy="0.000441450058332931"
        iyz="-9.45710654026833E-21"
        izz="0.000733078728294526" />
    </inertial>
    <visual>
      <origin
        xyz="0 0 0"
        rpy="0 0 0" />
      <geometry>
        <mesh
          filename="package://robot1/meshes/wheel_rf.STL" />
      </geometry>
      <material
        name="">
        <color
          rgba="0.792156862745098 0.819607843137255 0.933333333333333 1" />
      </material>
    </visual>
    <collision>
      <origin
        xyz="0 0 0"
        rpy="0 0 0" />
      <geometry>
        <mesh
          filename="package://robot1/meshes/wheel_rf.STL" />
      </geometry>
    </collision>
  </link>
  <joint
    name="wheel_rf"
    type="continuous">
    <origin
      xyz="0 -0.24 0"
      rpy="0 0 -0.514514776009117" />
    <parent
      link="leg_rf" />
    <child
      link="wheel_rf" />
    <axis
      xyz="0 0 1" />
  </joint>
  <link
    name="thigh_rb">
    <inertial>
      <origin
        xyz="0.00586303520723865 -0.057396329462197 -0.30825"
        rpy="0 0 0" />
      <mass
        value="0.0599999613849592" />
      <inertia
        ixx="0.000155906508351339"
        ixy="7.89182684103391E-21"
        ixz="-3.89894151664113E-21"
        iyy="1.13512134874171E-05"
        iyz="7.56925568087289E-21"
        izz="0.000165935222689895" />
    </inertial>
    <visual>
      <origin
        xyz="0 0 0"
        rpy="0 0 0" />
      <geometry>
        <mesh
          filename="package://robot1/meshes/thigh_rb.STL" />
      </geometry>
      <material
        name="">
        <color
          rgba="0.792156862745098 0.819607843137255 0.933333333333333 1" />
      </material>
    </visual>
    <collision>
      <origin
        xyz="0 0 0"
        rpy="0 0 0" />
      <geometry>
        <mesh
          filename="package://robot1/meshes/thigh_rb.STL" />
      </geometry>
    </collision>
  </link>
  <joint
    name="hip_rb"
    type="continuous">
    <origin
      xyz="0.0565864256571967 -0.1755 -0.00898586529801106"
      rpy="1.5707963267949 -1.5707963267949 0" />
    <parent
      link="body" />
    <child
      link="thigh_rb" />
    <axis
      xyz="0 0 -1" />
  </joint>
  <link
    name="leg_rb">
    <inertial>
      <origin
        xyz="-0.0070821732619874 -0.126171013878651 -0.30825"
        rpy="0 0 0" />
      <mass
        value="0.0750000161747867" />
      <inertia
        ixx="0.000553987900915234"
        ixy="-9.91028548287531E-20"
        ixz="-2.55732461281031E-21"
        iyy="9.43756802822444E-06"
        iyz="-6.95945538961423E-19"
        izz="0.000561772343586939" />
    </inertial>
    <visual>
      <origin
        xyz="0 0 0"
        rpy="0 0 0" />
      <geometry>
        <mesh
          filename="package://robot1/meshes/leg_rb.STL" />
      </geometry>
      <material
        name="">
        <color
          rgba="0.792156862745098 0.819607843137255 0.933333333333333 1" />
      </material>
    </visual>
    <collision>
      <origin
        xyz="0 0 0"
        rpy="0 0 0" />
      <geometry>
        <mesh
          filename="package://robot1/meshes/leg_rb.STL" />
      </geometry>
    </collision>
  </link>
  <joint
    name="knee_rb"
    type="continuous">
    <origin
      xyz="0 -0.14 0.0114999999999999"
      rpy="0 0 -2.46348623551965" />
    <parent
      link="thigh_rb" />
    <child
      link="leg_rb" />
    <axis
      xyz="0 0 1" />
  </joint>
  <link
    name="wheel_rb">
    <inertial>
      <origin
        xyz="-0.00150763839127392 0.00694200445991383 -0.33475"
        rpy="0 0 0" />
      <mass
        value="0.521949966745835" />
      <inertia
        ixx="0.000441450058332931"
        ixy="-1.35525271560688E-20"
        ixz="-2.0780683497093E-20"
        iyy="0.000441450058332931"
        iyz="-9.45710654026833E-21"
        izz="0.000733078728294526" />
    </inertial>
    <visual>
      <origin
        xyz="0 0 0"
        rpy="0 0 0" />
      <geometry>
        <mesh
          filename="package://robot1/meshes/wheel_rb.STL" />
      </geometry>
      <material
        name="">
        <color
          rgba="0.792156862745098 0.819607843137255 0.933333333333333 1" />
      </material>
    </visual>
    <collision>
      <origin
        xyz="0 0 0"
        rpy="0 0 0" />
      <geometry>
        <mesh
          filename="package://robot1/meshes/wheel_rb.STL" />
      </geometry>
    </collision>
  </link>
  <joint
    name="wheel_rb"
    type="continuous">
    <origin
      xyz="0 -0.24 0"
      rpy="0 0 1.27883674815523" />
    <parent
      link="leg_rb" />
    <child
      link="wheel_rb" />
    <axis
      xyz="0 0 1" />
  </joint>
</robot>