<?xml version="1.0" encoding="utf-8"?>
<!-- This URDF was automatically created by SolidWorks to URDF Exporter! Originally created by Stephen Brawner (brawner@gmail.com) 
     Commit Version: 1.6.0-1-g15f4949  Build Version: 1.6.7594.29634
     For more information, please see http://wiki.ros.org/sw_urdf_exporter -->
<robot
  name="robot">
  <link
    name="base_link">
    <inertial>
      <origin
        xyz="0 0 0"
        rpy="0 0 0" />
      <mass
        value="4.5635" />
      <inertia
        ixx="0.028098"
        ixy="7.1725E-20"
        ixz="-7.933E-17"
        iyy="0.037678"
        iyz="1.8054E-19"
        izz="0.016948" />
    </inertial>
    <visual>
      <origin
        xyz="0 0 0"
        rpy="0 0 0" />
      <geometry>
        <mesh
          filename="package://robot/meshes/base_link.STL" />
      </geometry>
      <material
        name="">
        <color
          rgba="0.79216 0.81961 0.93333 1" />
      </material>
    </visual>
    <collision>
      <origin
        xyz="0 0 0"
        rpy="0 0 0" />
      <geometry>
        <mesh
          filename="package://robot/meshes/base_link.STL" />
      </geometry>
    </collision>
  </link>
  <link
    name="hip2thigh_lf">
    <inertial>
      <origin
        xyz="6.1801E-18 -0.061407 -0.00575"
        rpy="0 0 0" />
      <mass
        value="0.06" />
      <inertia
        ixx="0.00015591"
        ixy="2.9461E-21"
        ixz="-9.3505E-21"
        iyy="1.1351E-05"
        iyz="-7.8953E-19"
        izz="0.00016594" />
    </inertial>
    <visual>
      <origin
        xyz="0 0 0"
        rpy="0 0 0" />
      <geometry>
        <mesh
          filename="package://robot/meshes/hip2thigh_lf.STL" />
      </geometry>
      <material
        name="">
        <color
          rgba="0.79216 0.81961 0.93333 1" />
      </material>
    </visual>
    <collision>
      <origin
        xyz="0 0 0"
        rpy="0 0 0" />
      <geometry>
        <mesh
          filename="package://robot/meshes/hip2thigh_lf.STL" />
      </geometry>
    </collision>
  </link>
  <joint
    name="hip_lf"
    type="continuous">
    <origin
      xyz="0.042425 0.157 0"
      rpy="1.5708 -1.5708 0" />
    <parent
      link="base_link" />
    <child
      link="hip2thigh_lf" />
    <axis
      xyz="0 0 -1" />
  </joint>
  <link
    name="thigh2leg_lf">
    <inertial>
      <origin
        xyz="0 -0.10565 -0.00575"
        rpy="0 0 0" />
      <mass
        value="0.0763" />
      <inertia
        ixx="0.00043722"
        ixy="1.6941E-21"
        ixz="1.9507E-20"
        iyy="7.4436E-06"
        iyz="1.4601E-18"
        izz="0.00044298" />
    </inertial>
    <visual>
      <origin
        xyz="0 0 0"
        rpy="0 0 0" />
      <geometry>
        <mesh
          filename="package://robot/meshes/thigh2leg_lf.STL" />
      </geometry>
      <material
        name="">
        <color
          rgba="0.79216 0.81961 0.93333 1" />
      </material>
    </visual>
    <collision>
      <origin
        xyz="0 0 0"
        rpy="0 0 0" />
      <geometry>
        <mesh
          filename="package://robot/meshes/thigh2leg_lf.STL" />
      </geometry>
    </collision>
  </link>
  <joint
    name="knee_lf"
    type="continuous">
    <origin
      xyz="0 -0.14 -0.0115"
      rpy="0 0 -2.4675" />
    <parent
      link="hip2thigh_lf" />
    <child
      link="thigh2leg_lf" />
    <axis
      xyz="0 0 1" />
  </joint>
  <link
    name="leg2wheel_lf">
    <inertial>
      <origin
        xyz="6.4185E-17 -8.3267E-17 0.02075"
        rpy="0 0 0" />
      <mass
        value="0.52195" />
      <inertia
        ixx="0.00044145"
        ixy="-1.6941E-21"
        ixz="2.0747E-18"
        iyy="0.00044145"
        iyz="-3.3823E-20"
        izz="0.00073308" />
    </inertial>
    <visual>
      <origin
        xyz="0 0 0"
        rpy="0 0 0" />
      <geometry>
        <mesh
          filename="package://robot/meshes/leg2wheel_lf.STL" />
      </geometry>
      <material
        name="">
        <color
          rgba="0.79216 0.81961 0.93333 1" />
      </material>
    </visual>
    <collision>
      <origin
        xyz="0 0 0"
        rpy="0 0 0" />
      <geometry>
        <mesh
          filename="package://robot/meshes/leg2wheel_lf.STL" />
      </geometry>
    </collision>
  </link>
  <joint
    name="foot_lf"
    type="continuous">
    <origin
      xyz="0 -0.24 0"
      rpy="0 0 0.82738" />
    <parent
      link="thigh2leg_lf" />
    <child
      link="leg2wheel_lf" />
    <axis
      xyz="0 0 1" />
  </joint>
  <link
    name="hip2thigh_lb">
    <inertial>
      <origin
        xyz="-2.22041654777272E-18 -0.061407466158819 -0.0057500000000007"
        rpy="0 0 0" />
      <mass
        value="0.0539995474696858" />
      <inertia
        ixx="0.000140314771946862"
        ixy="-7.43235680079296E-21"
        ixz="6.14097015851312E-21"
        iyy="1.02160131007346E-05"
        iyz="6.95243980379891E-19"
        izz="0.000149340545022119" />
    </inertial>
    <visual>
      <origin
        xyz="0 0 0"
        rpy="0 0 0" />
      <geometry>
        <mesh
          filename="package://robot/meshes/hip2thigh_lb.STL" />
      </geometry>
      <material
        name="">
        <color
          rgba="0.792156862745098 0.819607843137255 0.933333333333333 1" />
      </material>
    </visual>
    <collision>
      <origin
        xyz="0 0 0"
        rpy="0 0 0" />
      <geometry>
        <mesh
          filename="package://robot/meshes/hip2thigh_lb.STL" />
      </geometry>
    </collision>
  </link>
  <joint
    name="hip_lb"
    type="continuous">
    <origin
      xyz="-0.052575 0.127 0"
      rpy="1.5708 1.5708 0" />
    <parent
      link="base_link" />
    <child
      link="hip2thigh_lb" />
    <axis
      xyz="0 0 -1" />
  </joint>
  <link
    name="thigh2leg_lb">
    <inertial>
      <origin
        xyz="2.77555756156289E-17 -0.126725289376484 0.00574999999999845"
        rpy="0 0 0" />
      <mass
        value="0.0750000161747868" />
      <inertia
        ixx="0.000553987900915235"
        ixy="-5.84452733605467E-20"
        ixz="1.65199332220617E-20"
        iyy="9.43756802822454E-06"
        iyz="-3.30067461314353E-18"
        izz="0.00056177234358694" />
    </inertial>
    <visual>
      <origin
        xyz="0 0 0"
        rpy="0 0 0" />
      <geometry>
        <mesh
          filename="package://robot/meshes/thigh2leg_lb.STL" />
      </geometry>
      <material
        name="">
        <color
          rgba="0.792156862745098 0.819607843137255 0.933333333333333 1" />
      </material>
    </visual>
    <collision>
      <origin
        xyz="0 0 0"
        rpy="0 0 0" />
      <geometry>
        <mesh
          filename="package://robot/meshes/thigh2leg_lb.STL" />
      </geometry>
    </collision>
  </link>
  <joint
    name="knee_lb"
    type="continuous">
    <origin
      xyz="0 -0.14 0"
      rpy="0 0 2.46746214692248" />
    <parent
      link="hip2thigh_lb" />
    <child
      link="thigh2leg_lb" />
    <axis
      xyz="0 0 1" />
  </joint>
  <link
    name="leg2wheel_lb">
    <inertial>
      <origin
        xyz="-1.15359111152458E-16 -5.55111512312578E-17 -0.0207500000000007"
        rpy="0 0 0" />
      <mass
        value="0.521949966745835" />
      <inertia
        ixx="0.000441450058332931"
        ixy="-1.6940658945086E-21"
        ixz="2.07466425242616E-18"
        iyy="0.000441450058332931"
        iyz="-3.38231691806901E-20"
        izz="0.000733078728294525" />
    </inertial>
    <visual>
      <origin
        xyz="0 0 0"
        rpy="0 0 0" />
      <geometry>
        <mesh
          filename="package://robot/meshes/leg2wheel_lb.STL" />
      </geometry>
      <material
        name="">
        <color
          rgba="0.792156862745098 0.819607843137255 0.933333333333333 1" />
      </material>
    </visual>
    <collision>
      <origin
        xyz="0 0 0"
        rpy="0 0 0" />
      <geometry>
        <mesh
          filename="package://robot/meshes/leg2wheel_lb.STL" />
      </geometry>
    </collision>
  </link>
  <joint
    name="foot_lb"
    type="continuous">
    <origin
      xyz="0 -0.24 0"
      rpy="0 0 -0.965954301349358" />
    <parent
      link="thigh2leg_lb" />
    <child
      link="leg2wheel_lb" />
    <axis
      xyz="0 0 1" />
  </joint>
  <link
    name="hip2thigh_rf">
    <inertial>
      <origin
        xyz="3.85525815338172E-18 -0.061407466158819 0.00575000000000089"
        rpy="0 0 0" />
      <mass
        value="0.0599999613849593" />
      <inertia
        ixx="0.000155906508351339"
        ixy="9.73323749888728E-21"
        ixz="3.73574741794094E-24"
        iyy="1.13512134874171E-05"
        iyz="-1.08504933903155E-18"
        izz="0.000165935222689896" />
    </inertial>
    <visual>
      <origin
        xyz="0 0 0"
        rpy="0 0 0" />
      <geometry>
        <mesh
          filename="package://robot/meshes/hip2thigh_rf.STL" />
      </geometry>
      <material
        name="">
        <color
          rgba="0.792156862745098 0.819607843137255 0.933333333333333 1" />
      </material>
    </visual>
    <collision>
      <origin
        xyz="0 0 0"
        rpy="0 0 0" />
      <geometry>
        <mesh
          filename="package://robot/meshes/hip2thigh_rf.STL" />
      </geometry>
    </collision>
  </link>
  <joint
    name="hip_rf"
    type="continuous">
    <origin
      xyz="0.042425 -0.157 0"
      rpy="1.5708 -1.5708 0" />
    <parent
      link="base_link" />
    <child
      link="hip2thigh_rf" />
    <axis
      xyz="0 0 1" />
  </joint>
  <link
    name="thigh2leg_rf">
    <inertial>
      <origin
        xyz="4.16333634234434E-17 -0.105647585166419 0.00575000000000225"
        rpy="0 0 0" />
      <mass
        value="0.0763000411167858" />
      <inertia
        ixx="0.000437218386664754"
        ixy="-5.84452733605467E-20"
        ixz="2.47571227334978E-20"
        iyy="7.44363321133752E-06"
        iyz="2.37301864809742E-18"
        izz="0.000442980239803142" />
    </inertial>
    <visual>
      <origin
        xyz="0 0 0"
        rpy="0 0 0" />
      <geometry>
        <mesh
          filename="package://robot/meshes/thigh2leg_rf.STL" />
      </geometry>
      <material
        name="">
        <color
          rgba="0.792156862745098 0.819607843137255 0.933333333333333 1" />
      </material>
    </visual>
    <collision>
      <origin
        xyz="0 0 0"
        rpy="0 0 0" />
      <geometry>
        <mesh
          filename="package://robot/meshes/thigh2leg_rf.STL" />
      </geometry>
    </collision>
  </link>
  <joint
    name="knee_rf"
    type="continuous">
    <origin
      xyz="0 -0.14 0.0114999999999986"
      rpy="0 0 -2.46746214692248" />
    <parent
      link="hip2thigh_rf" />
    <child
      link="thigh2leg_rf" />
    <axis
      xyz="0 0 1" />
  </joint>
  <link
    name="leg2wheel_rf">
    <inertial>
      <origin
        xyz="5.55111512312578E-17 -1.2490009027033E-16 -0.0207499999999983"
        rpy="0 0 0" />
      <mass
        value="0.521949966745835" />
      <inertia
        ixx="0.00044145005833293"
        ixy="-6.7762635780344E-20"
        ixz="-9.00265480038554E-19"
        iyy="0.00044145005833293"
        iyz="1.86202171434693E-18"
        izz="0.000733078728294525" />
    </inertial>
    <visual>
      <origin
        xyz="0 0 0"
        rpy="0 0 0" />
      <geometry>
        <mesh
          filename="package://robot/meshes/leg2wheel_rf.STL" />
      </geometry>
      <material
        name="">
        <color
          rgba="0.792156862745098 0.819607843137255 0.933333333333333 1" />
      </material>
    </visual>
    <collision>
      <origin
        xyz="0 0 0"
        rpy="0 0 0" />
      <geometry>
        <mesh
          filename="package://robot/meshes/leg2wheel_rf.STL" />
      </geometry>
    </collision>
  </link>
  <joint
    name="foot_rf"
    type="continuous">
    <origin
      xyz="0 -0.24 0"
      rpy="0 0 -1.15869988791543" />
    <parent
      link="thigh2leg_rf" />
    <child
      link="leg2wheel_rf" />
    <axis
      xyz="0 0 1" />
  </joint>
  <link
    name="hip2thigh_rb">
    <inertial>
      <origin
        xyz="0 0 0"
        rpy="0 0 0" />
      <mass
        value="0" />
      <inertia
        ixx="0"
        ixy="0"
        ixz="0"
        iyy="0"
        iyz="0"
        izz="0" />
    </inertial>
    <visual>
      <origin
        xyz="0 0 0"
        rpy="0 0 0" />
      <geometry>
        <mesh
          filename="package://robot/meshes/hip2thigh_rb.STL" />
      </geometry>
      <material
        name="">
        <color
          rgba="1 1 1 1" />
      </material>
    </visual>
    <collision>
      <origin
        xyz="0 0 0"
        rpy="0 0 0" />
      <geometry>
        <mesh
          filename="package://robot/meshes/hip2thigh_rb.STL" />
      </geometry>
    </collision>
  </link>
  <joint
    name="hip_rb"
    type="continuous">
    <origin
      xyz="-0.0525752889605738 -0.126999999999999 0"
      rpy="1.5707963267949 1.5707963267949 0" />
    <parent
      link="base_link" />
    <child
      link="hip2thigh_rb" />
    <axis
      xyz="0 0 1" />
  </joint>
  <link
    name="thigh2leg_rb">
    <inertial>
      <origin
        xyz="1.38777878078145E-17 -0.126725289376484 -0.00574999999999939"
        rpy="0 0 0" />
      <mass
        value="0.0750000161747868" />
      <inertia
        ixx="0.000553987900915235"
        ixy="4.61632956253594E-20"
        ixz="3.55050933537804E-20"
        iyy="9.43756802822455E-06"
        iyz="-3.08532215205517E-18"
        izz="0.00056177234358694" />
    </inertial>
    <visual>
      <origin
        xyz="0 0 0"
        rpy="0 0 0" />
      <geometry>
        <mesh
          filename="package://robot/meshes/thigh2leg_rb.STL" />
      </geometry>
      <material
        name="">
        <color
          rgba="0.792156862745098 0.819607843137255 0.933333333333333 1" />
      </material>
    </visual>
    <collision>
      <origin
        xyz="0 0 0"
        rpy="0 0 0" />
      <geometry>
        <mesh
          filename="package://robot/meshes/thigh2leg_rb.STL" />
      </geometry>
    </collision>
  </link>
  <joint
    name="knee_rb"
    type="continuous">
    <origin
      xyz="0 -0.14 0"
      rpy="0 0 2.46746214692248" />
    <parent
      link="hip2thigh_rb" />
    <child
      link="thigh2leg_rb" />
    <axis
      xyz="0 0 1" />
  </joint>
  <link
    name="leg2wheel_rb">
    <inertial>
      <origin
        xyz="-8.32667268468867E-17 1.2490009027033E-16 0.020750000000001"
        rpy="0 0 0" />
      <mass
        value="0.521949966745835" />
      <inertia
        ixx="0.00044145005833293"
        ixy="-6.7762635780344E-20"
        ixz="-9.00265480038554E-19"
        iyy="0.00044145005833293"
        iyz="1.86202171434693E-18"
        izz="0.000733078728294525" />
    </inertial>
    <visual>
      <origin
        xyz="0 0 0"
        rpy="0 0 0" />
      <geometry>
        <mesh
          filename="package://robot/meshes/leg2wheel_rb.STL" />
      </geometry>
      <material
        name="">
        <color
          rgba="0.792156862745098 0.819607843137255 0.933333333333333 1" />
      </material>
    </visual>
    <collision>
      <origin
        xyz="0 0 0"
        rpy="0 0 0" />
      <geometry>
        <mesh
          filename="package://robot/meshes/leg2wheel_rb.STL" />
      </geometry>
    </collision>
  </link>
  <joint
    name="foot_rb"
    type="continuous">
    <origin
      xyz="0 -0.24 0"
      rpy="0 0 -2.95203152817059" />
    <parent
      link="thigh2leg_rb" />
    <child
      link="leg2wheel_rb" />
    <axis
      xyz="0 0 1" />
  </joint>
</robot>