<?xml version="1.0" encoding="utf-8"?>
<!-- This URDF was automatically created by SolidWorks to URDF Exporter! Originally created by Stephen Brawner (brawner@gmail.com) 
     Commit Version: 1.6.0-1-g15f4949  Build Version: 1.6.7594.29634
     For more information, please see http://wiki.ros.org/sw_urdf_exporter -->
<robot
  name="robot0724">
  <link
    name="base_link">
    <inertial>
      <origin
        xyz="7.99587161808179E-18 2.92200512446113E-18 -2.4772664067657E-18"
        rpy="0 0 0" />
      <mass
        value="4.563502045004" />
      <inertia
        ixx="0.0280984473320404"
        ixy="7.98291326472171E-17"
        ixz="2.661110932328E-20"
        iyy="0.0169477927066625"
        iyz="1.08880015646914E-18"
        izz="0.0376783082336192" />
    </inertial>
    <visual>
      <origin
        xyz="0 0 0"
        rpy="0 0 0" />
      <geometry>
        <mesh
          filename="E:/Robot0/robot0724/meshes/base_link.STL" />
      </geometry>
      <material
        name="">
        <color
          rgba="0.792156862745098 0.819607843137255 0.933333333333333 1" />
      </material>
    </visual>
    <collision>
      <origin
        xyz="0 0 0"
        rpy="0 0 0" />
      <geometry>
        <mesh
          filename="E:/Robot0/robot0724/meshes/base_link.STL" />
      </geometry>
    </collision>
  </link>
  <link
    name="hip2thigh_lf">
    <inertial>
      <origin
        xyz="5.8976096206088E-18 -0.0614074661588189 -0.00575000000000156"
        rpy="0 0 0" />
      <mass
        value="0.0599999613849592" />
      <inertia
        ixx="0.000155906508351339"
        ixy="3.61515635246786E-21"
        ixz="-9.29821239626968E-21"
        iyy="1.13512134874171E-05"
        iyz="-7.88663105245101E-19"
        izz="0.000165935222689896" />
    </inertial>
    <visual>
      <origin
        xyz="0 0 0"
        rpy="0 0 0" />
      <geometry>
        <mesh
          filename="E:/Robot0/robot0724/meshes/hip2thigh_lf.STL" />
      </geometry>
      <material
        name="">
        <color
          rgba="0.792156862745098 0.819607843137255 0.933333333333333 1" />
      </material>
    </visual>
    <collision>
      <origin
        xyz="0 0 0"
        rpy="0 0 0" />
      <geometry>
        <mesh
          filename="E:/Robot0/robot0724/meshes/hip2thigh_lf.STL" />
      </geometry>
    </collision>
  </link>
  <joint
    name="hip_lf"
    type="continuous">
    <origin
      xyz="0.0424247110394242 0.156999999999999 0"
      rpy="1.5707963267949 -1.5707963267949 0" />
    <parent
      link="base_link" />
    <child
      link="hip2thigh_lf" />
    <axis
      xyz="0 0 1" />
  </joint>
  <link
    name="thigh2leg_lf">
    <inertial>
      <origin
        xyz="2.77555756156289E-17 -0.10564758516642 -0.00575000000000067"
        rpy="0 0 0" />
      <mass
        value="0.0763000411167859" />
      <inertia
        ixx="0.000437218386664755"
        ixy="3.9387032047325E-20"
        ixz="2.04860565874082E-20"
        iyy="7.44363321133751E-06"
        iyz="1.46095006576192E-18"
        izz="0.000442980239803143" />
    </inertial>
    <visual>
      <origin
        xyz="0 0 0"
        rpy="0 0 0" />
      <geometry>
        <mesh
          filename="E:/Robot0/robot0724/meshes/thigh2leg_lf.STL" />
      </geometry>
      <material
        name="">
        <color
          rgba="0.792156862745098 0.819607843137255 0.933333333333333 1" />
      </material>
    </visual>
    <collision>
      <origin
        xyz="0 0 0"
        rpy="0 0 0" />
      <geometry>
        <mesh
          filename="E:/Robot0/robot0724/meshes/thigh2leg_lf.STL" />
      </geometry>
    </collision>
  </link>
  <joint
    name="knee_lf"
    type="continuous">
    <origin
      xyz="0 -0.14 -0.011500000000001"
      rpy="0 0 -2.46746214692248" />
    <parent
      link="hip2thigh_lf" />
    <child
      link="thigh2leg_lf" />
    <axis
      xyz="0 0 1" />
  </joint>
  <link
    name="leg2wheel_lf">
    <inertial>
      <origin
        xyz="6.41847686111419E-17 -8.32667268468867E-17 0.0207499999999986"
        rpy="0 0 0" />
      <mass
        value="0.521949966745835" />
      <inertia
        ixx="0.000441450058332931"
        ixy="-1.6940658945086E-21"
        ixz="2.07466425242616E-18"
        iyy="0.000441450058332931"
        iyz="-3.38231691806899E-20"
        izz="0.000733078728294525" />
    </inertial>
    <visual>
      <origin
        xyz="0 0 0"
        rpy="0 0 0" />
      <geometry>
        <mesh
          filename="E:/Robot0/robot0724/meshes/leg2wheel_lf.STL" />
      </geometry>
      <material
        name="">
        <color
          rgba="0.792156862745098 0.819607843137255 0.933333333333333 1" />
      </material>
    </visual>
    <collision>
      <origin
        xyz="0 0 0"
        rpy="0 0 0" />
      <geometry>
        <mesh
          filename="E:/Robot0/robot0724/meshes/leg2wheel_lf.STL" />
      </geometry>
    </collision>
  </link>
  <joint
    name="foot_lf"
    type="continuous">
    <origin
      xyz="0 -0.24 0"
      rpy="0 0 0.827377338905804" />
    <parent
      link="thigh2leg_lf" />
    <child
      link="leg2wheel_lf" />
    <axis
      xyz="0 0 1" />
  </joint>
  <link
    name="hip2thigh_lb">
    <inertial>
      <origin
        xyz="-1.66286028071222E-18 -0.061407466158819 -0.0057500000000007"
        rpy="0 0 0" />
      <mass
        value="0.0539995474696859" />
      <inertia
        ixx="0.000140314771946862"
        ixy="-7.87581422637996E-21"
        ixz="6.37611876466593E-21"
        iyy="1.02160131007346E-05"
        iyz="6.95811135105747E-19"
        izz="0.000149340545022119" />
    </inertial>
    <visual>
      <origin
        xyz="0 0 0"
        rpy="0 0 0" />
      <geometry>
        <mesh
          filename="E:/Robot0/robot0724/meshes/hip2thigh_lb.STL" />
      </geometry>
      <material
        name="">
        <color
          rgba="0.792156862745098 0.819607843137255 0.933333333333333 1" />
      </material>
    </visual>
    <collision>
      <origin
        xyz="0 0 0"
        rpy="0 0 0" />
      <geometry>
        <mesh
          filename="E:/Robot0/robot0724/meshes/hip2thigh_lb.STL" />
      </geometry>
    </collision>
  </link>
  <joint
    name="hip_lb"
    type="continuous">
    <origin
      xyz="-0.0525752889605756 0.126999999999999 0"
      rpy="1.5707963267949 1.5707963267949 0" />
    <parent
      link="base_link" />
    <child
      link="hip2thigh_lb" />
    <axis
      xyz="0 0 1" />
  </joint>
  <link
    name="thigh2leg_lb">
    <inertial>
      <origin
        xyz="2.77555756156289E-17 -0.126725289376484 0.00574999999999845"
        rpy="0 0 0" />
      <mass
        value="0.0750000161747868" />
      <inertia
        ixx="0.000553987900915235"
        ixy="-6.69156028330897E-20"
        ixz="1.76880715720282E-20"
        iyy="9.43756802822456E-06"
        iyz="-3.30067652808097E-18"
        izz="0.00056177234358694" />
    </inertial>
    <visual>
      <origin
        xyz="0 0 0"
        rpy="0 0 0" />
      <geometry>
        <mesh
          filename="E:/Robot0/robot0724/meshes/thigh2leg_lb.STL" />
      </geometry>
      <material
        name="">
        <color
          rgba="0.792156862745098 0.819607843137255 0.933333333333333 1" />
      </material>
    </visual>
    <collision>
      <origin
        xyz="0 0 0"
        rpy="0 0 0" />
      <geometry>
        <mesh
          filename="E:/Robot0/robot0724/meshes/thigh2leg_lb.STL" />
      </geometry>
    </collision>
  </link>
  <joint
    name="knee_lb"
    type="continuous">
    <origin
      xyz="0 -0.14 0"
      rpy="0 0 2.46746214692248" />
    <parent
      link="hip2thigh_lb" />
    <child
      link="thigh2leg_lb" />
    <axis
      xyz="0 0 1" />
  </joint>
  <link
    name="leg2wheel_lb">
    <inertial>
      <origin
        xyz="-1.15359111152458E-16 -5.55111512312578E-17 -0.0207500000000007"
        rpy="0 0 0" />
      <mass
        value="0.521949966745835" />
      <inertia
        ixx="0.000441450058332931"
        ixy="-1.6940658945086E-21"
        ixz="2.07466425242616E-18"
        iyy="0.000441450058332931"
        iyz="-3.38231691806899E-20"
        izz="0.000733078728294525" />
    </inertial>
    <visual>
      <origin
        xyz="0 0 0"
        rpy="0 0 0" />
      <geometry>
        <mesh
          filename="E:/Robot0/robot0724/meshes/leg2wheel_lb.STL" />
      </geometry>
      <material
        name="">
        <color
          rgba="0.792156862745098 0.819607843137255 0.933333333333333 1" />
      </material>
    </visual>
    <collision>
      <origin
        xyz="0 0 0"
        rpy="0 0 0" />
      <geometry>
        <mesh
          filename="E:/Robot0/robot0724/meshes/leg2wheel_lb.STL" />
      </geometry>
    </collision>
  </link>
  <joint
    name="foot_lb"
    type="continuous">
    <origin
      xyz="0 -0.24 0"
      rpy="0 0 -0.965954301349358" />
    <parent
      link="thigh2leg_lb" />
    <child
      link="leg2wheel_lb" />
    <axis
      xyz="0 0 1" />
  </joint>
  <link
    name="hip2thigh_rf">
    <inertial>
      <origin
        xyz="3.85525815338172E-18 -0.061407466158819 0.00575000000000089"
        rpy="0 0 0" />
      <mass
        value="0.0599999613849593" />
      <inertia
        ixx="0.000155906508351339"
        ixy="1.11706863247829E-20"
        ixz="-1.66095115385664E-22"
        iyy="1.13512134874171E-05"
        iyz="-1.08588542943304E-18"
        izz="0.000165935222689896" />
    </inertial>
    <visual>
      <origin
        xyz="0 0 0"
        rpy="0 0 0" />
      <geometry>
        <mesh
          filename="E:/Robot0/robot0724/meshes/hip2thigh_rf.STL" />
      </geometry>
      <material
        name="">
        <color
          rgba="0.792156862745098 0.819607843137255 0.933333333333333 1" />
      </material>
    </visual>
    <collision>
      <origin
        xyz="0 0 0"
        rpy="0 0 0" />
      <geometry>
        <mesh
          filename="E:/Robot0/robot0724/meshes/hip2thigh_rf.STL" />
      </geometry>
    </collision>
  </link>
  <joint
    name="hip_rf"
    type="continuous">
    <origin
      xyz="0.0424247110394264 -0.156999999999998 0"
      rpy="1.5707963267949 -1.5707963267949 0" />
    <parent
      link="base_link" />
    <child
      link="hip2thigh_rf" />
    <axis
      xyz="0 0 1" />
  </joint>
  <link
    name="thigh2leg_rf">
    <inertial>
      <origin
        xyz="4.16333634234434E-17 -0.105647585166419 0.00575000000000225"
        rpy="0 0 0" />
      <mass
        value="0.0763000411167858" />
      <inertia
        ixx="0.000437218386664754"
        ixy="-1.01643953670516E-20"
        ixz="2.46160819726033E-20"
        iyy="7.44363321133749E-06"
        iyz="2.37322169284635E-18"
        izz="0.000442980239803142" />
    </inertial>
    <visual>
      <origin
        xyz="0 0 0"
        rpy="0 0 0" />
      <geometry>
        <mesh
          filename="E:/Robot0/robot0724/meshes/thigh2leg_rf.STL" />
      </geometry>
      <material
        name="">
        <color
          rgba="0.792156862745098 0.819607843137255 0.933333333333333 1" />
      </material>
    </visual>
    <collision>
      <origin
        xyz="0 0 0"
        rpy="0 0 0" />
      <geometry>
        <mesh
          filename="E:/Robot0/robot0724/meshes/thigh2leg_rf.STL" />
      </geometry>
    </collision>
  </link>
  <joint
    name="knee_rf"
    type="continuous">
    <origin
      xyz="0 -0.14 0.0114999999999986"
      rpy="0 0 -2.46746214692248" />
    <parent
      link="hip2thigh_rf" />
    <child
      link="thigh2leg_rf" />
    <axis
      xyz="0 0 1" />
  </joint>
  <link
    name="leg2wheel_rf">
    <inertial>
      <origin
        xyz="5.55111512312578E-17 -1.2490009027033E-16 -0.0207499999999983"
        rpy="0 0 0" />
      <mass
        value="0.521949966745835" />
      <inertia
        ixx="0.00044145005833293"
        ixy="-5.42101086242752E-20"
        ixz="-9.04620483953524E-19"
        iyy="0.00044145005833293"
        iyz="1.85595464493957E-18"
        izz="0.000733078728294525" />
    </inertial>
    <visual>
      <origin
        xyz="0 0 0"
        rpy="0 0 0" />
      <geometry>
        <mesh
          filename="E:/Robot0/robot0724/meshes/leg2wheel_rf.STL" />
      </geometry>
      <material
        name="">
        <color
          rgba="0.792156862745098 0.819607843137255 0.933333333333333 1" />
      </material>
    </visual>
    <collision>
      <origin
        xyz="0 0 0"
        rpy="0 0 0" />
      <geometry>
        <mesh
          filename="E:/Robot0/robot0724/meshes/leg2wheel_rf.STL" />
      </geometry>
    </collision>
  </link>
  <joint
    name="foot_rf"
    type="continuous">
    <origin
      xyz="0 -0.24 0"
      rpy="0 0 -1.15869988791543" />
    <parent
      link="thigh2leg_rf" />
    <child
      link="leg2wheel_rf" />
    <axis
      xyz="0 0 1" />
  </joint>
  <link
    name="hip2thigh_rb">
    <inertial>
      <origin
        xyz="2.34818829585434E-18 -0.0614074661588188 0.0057500000000017"
        rpy="0 0 0" />
      <mass
        value="0.0539995474696858" />
      <inertia
        ixx="0.000140314771946862"
        ixy="1.37198865292877E-20"
        ixz="-8.81747113664116E-24"
        iyy="1.02160131007346E-05"
        iyz="9.65351109926132E-19"
        izz="0.000149340545022119" />
    </inertial>
    <visual>
      <origin
        xyz="0 0 0"
        rpy="0 0 0" />
      <geometry>
        <mesh
          filename="E:/Robot0/robot0724/meshes/hip2thigh_rb.STL" />
      </geometry>
      <material
        name="">
        <color
          rgba="0.792156862745098 0.819607843137255 0.933333333333333 1" />
      </material>
    </visual>
    <collision>
      <origin
        xyz="0 0 0"
        rpy="0 0 0" />
      <geometry>
        <mesh
          filename="E:/Robot0/robot0724/meshes/hip2thigh_rb.STL" />
      </geometry>
    </collision>
  </link>
  <joint
    name="hip_rb"
    type="continuous">
    <origin
      xyz="-0.0525752889605738 -0.126999999999999 0"
      rpy="1.5707963267949 1.5707963267949 0" />
    <parent
      link="base_link" />
    <child
      link="hip2thigh_rb" />
    <axis
      xyz="0 0 1" />
  </joint>
  <link
    name="thigh2leg_rb">
    <inertial>
      <origin
        xyz="0 -0.126725289376484 -0.00574999999999939"
        rpy="0 0 0" />
      <mass
        value="0.0750000161747868" />
      <inertia
        ixx="0.000553987900915235"
        ixy="8.470329472543E-21"
        ixz="3.54650899010835E-20"
        iyy="9.43756802822453E-06"
        iyz="-3.08419408111425E-18"
        izz="0.00056177234358694" />
    </inertial>
    <visual>
      <origin
        xyz="0 0 0"
        rpy="0 0 0" />
      <geometry>
        <mesh
          filename="E:/Robot0/robot0724/meshes/thigh2leg_rb.STL" />
      </geometry>
      <material
        name="">
        <color
          rgba="0.792156862745098 0.819607843137255 0.933333333333333 1" />
      </material>
    </visual>
    <collision>
      <origin
        xyz="0 0 0"
        rpy="0 0 0" />
      <geometry>
        <mesh
          filename="E:/Robot0/robot0724/meshes/thigh2leg_rb.STL" />
      </geometry>
    </collision>
  </link>
  <joint
    name="knee_rb"
    type="continuous">
    <origin
      xyz="0 -0.14 0"
      rpy="0 0 2.46746214692248" />
    <parent
      link="hip2thigh_rb" />
    <child
      link="thigh2leg_rb" />
    <axis
      xyz="0 0 1" />
  </joint>
  <link
    name="leg2wheel_rb">
    <inertial>
      <origin
        xyz="-8.32667268468867E-17 1.2490009027033E-16 0.020750000000001"
        rpy="0 0 0" />
      <mass
        value="0.521949966745835" />
      <inertia
        ixx="0.00044145005833293"
        ixy="-5.42101086242752E-20"
        ixz="-9.04620483953524E-19"
        iyy="0.00044145005833293"
        iyz="1.85595464493957E-18"
        izz="0.000733078728294525" />
    </inertial>
    <visual>
      <origin
        xyz="0 0 0"
        rpy="0 0 0" />
      <geometry>
        <mesh
          filename="E:/Robot0/robot0724/meshes/leg2wheel_rb.STL" />
      </geometry>
      <material
        name="">
        <color
          rgba="0.792156862745098 0.819607843137255 0.933333333333333 1" />
      </material>
    </visual>
    <collision>
      <origin
        xyz="0 0 0"
        rpy="0 0 0" />
      <geometry>
        <mesh
          filename="E:/Robot0/robot0724/meshes/leg2wheel_rb.STL" />
      </geometry>
    </collision>
  </link>
  <joint
    name="foot_rb"
    type="continuous">
    <origin
      xyz="0 -0.24 0"
      rpy="0 0 -2.95203152817059" />
    <parent
      link="thigh2leg_rb" />
    <child
      link="leg2wheel_rb" />
    <axis
      xyz="0 0 1" />
  </joint>
</robot>